Workbook

Sheet Offers
A1: ID | B1: Nome | C1: Progetto | D1: Anno | E1: Stato | F1: REY | G1: Importo finale | H1: Importo in offerta | I1: Sconto | J1: Prepara Offerta
B2: Leonardo - Elastic POC and stress/performance testing | C2: Leonardo | D2: 2025 | E2: Fatturata | F2: REYIT24-13133 | G2: {=SUMPRODUCT(('Budget Lines - Leonardo'!$F$2:$F$1526=Offers!B2)*('Budget Lines - Leonardo'!$G$2:$G$1526))} -> 45580 | H2: 45580 | I2: =Tabella1[[#This Row],[Importo in offerta]]-Tabella1[[#This Row],[Importo finale]] -> 0
B3: Leonardo - Login Optimization | C3: Leonardo | D3: 2025 | E3: Fatturata | F3: REYIT24-10651 | G3: {=SUMPRODUCT(('Budget Lines - Leonardo'!$F$2:$F$1526=Offers!B3)*('Budget Lines - Leonardo'!$G$2:$G$1526))} -> 42145 | H3: 42790 | I3: =Tabella1[[#This Row],[Importo in offerta]]-Tabella1[[#This Row],[Importo finale]] -> 645
B4: Leonardo - CMS new Pages implementation | C4: Leonardo | D4: 2025 | E4: Fatturata | F4: REYIT24-10650 | G4: {=SUMPRODUCT(('Budget Lines - Leonardo'!$F$2:$F$1526=Offers!B4)*('Budget Lines - Leonardo'!$G$2:$G$1526))} -> 41560 | H4: 41710 | I4: =Tabella1[[#This Row],[Importo in offerta]]-Tabella1[[#This Row],[Importo finale]] -> 150
B5: Leonardo - Teams / Vimeo & LS / VC | C5: Leonardo | D5: 2025 | E5: Fatturata | F5: REYIT25-02204 | G5: {=SUMPRODUCT(('Budget Lines - Leonardo'!$F$2:$F$1526=Offers!B5)*('Budget Lines - Leonardo'!$G$2:$G$1526))} -> 26230 | H5: 26230 | I5: =Tabella1[[#This Row],[Importo in offerta]]-Tabella1[[#This Row],[Importo finale]] -> 0
B6: Leonardo - Internal Audit | C6: Leonardo | D6: 2025 | E6: Fatturata | F6: REYIT25-02338 | G6: {=SUMPRODUCT(('Budget Lines - Leonardo'!$F$2:$F$1526=Offers!B6)*('Budget Lines - Leonardo'!$G$2:$G$1526))} -> 16985 | H6: 16985 | I6: =Tabella1[[#This Row],[Importo in offerta]]-Tabella1[[#This Row],[Importo finale]] -> 0
B7: Leornado - CMS Module Expert | C7: Leonardo | D7: 2025 | E7: Fatturata | F7: REYIT25-02491 | G7: {=SUMPRODUCT(('Budget Lines - Leonardo'!$F$2:$F$1526=Offers!B7)*('Budget Lines - Leonardo'!$G$2:$G$1526))} -> 29440 | H7: 30100 | I7: =Tabella1[[#This Row],[Importo in offerta]]-Tabella1[[#This Row],[Importo finale]] -> 660
B8: Leonardo - Onboarding Semplification (pt2) | C8: Leonardo | D8: 2025 | E8: Fatturata | F8: REYIT25-02607 | G8: {=SUMPRODUCT(('Budget Lines - Leonardo'!$F$2:$F$1526=Offers!B8)*('Budget Lines - Leonardo'!$G$2:$G$1526))} -> 12310 | H8: 12900 | I8: =Tabella1[[#This Row],[Importo in offerta]]-Tabella1[[#This Row],[Importo finale]] -> 590
B9: Leonardo - Manager Assignment and Reassignment | C9: Leonardo | D9: 2025 | E9: Fatturata | F9: REYIT25-02791 | G9: {=SUMPRODUCT(('Budget Lines - Leonardo'!$F$2:$F$1526=Offers!B9)*('Budget Lines - Leonardo'!$G$2:$G$1526))} -> 49880 | H9: 49970 | I9: =Tabella1[[#This Row],[Importo in offerta]]-Tabella1[[#This Row],[Importo finale]] -> 90
B10: Leonardo - Learning Program Visibility Optional | C10: Leonardo | D10: 2025 | E10: Fatturata | F10: REYIT25-02790 | G10: {=SUMPRODUCT(('Budget Lines - Leonardo'!$F$2:$F$1526=Offers!B10)*('Budget Lines - Leonardo'!$G$2:$G$1526))} -> 37940 | H10: 38700 | I10: =Tabella1[[#This Row],[Importo in offerta]]-Tabella1[[#This Row],[Importo finale]] -> 760
B11: Leonardo - Content Language new development | C11: Leonardo | D11: 2025 | E11: Fatturata | F11: REYIT25-02908 | G11: {=SUMPRODUCT(('Budget Lines - Leonardo'!$F$2:$F$1526=Offers!B11)*('Budget Lines - Leonardo'!$G$2:$G$1526))} -> 47300 | H11: 47300 | I11: =Tabella1[[#This Row],[Importo in offerta]]-Tabella1[[#This Row],[Importo finale]] -> 0
B12: Leonardo - BFF Refactoring and Remodelling | C12: Leonardo | D12: 2025 | E12: Fatturata | F12: REYIT25-02969 | G12: {=SUMPRODUCT(('Budget Lines - Leonardo'!$F$2:$F$1526=Offers!B12)*('Budget Lines - Leonardo'!$G$2:$G$1526))} -> 49020 | H12: 49020 | I12: =Tabella1[[#This Row],[Importo in offerta]]-Tabella1[[#This Row],[Importo finale]] -> 0
B13: Leonardo - Course Catalog migration on SOLR | C13: Leonardo | D13: 2025 | E13: Fatturata | F13: REYIT25-02909 | G13: {=SUMPRODUCT(('Budget Lines - Leonardo'!$F$2:$F$1526=Offers!B13)*('Budget Lines - Leonardo'!$G$2:$G$1526))} -> 40560 | H13: 41280 | I13: =Tabella1[[#This Row],[Importo in offerta]]-Tabella1[[#This Row],[Importo finale]] -> 720
... B22: Leonardo - CRPACK Q3 | C22: Leonardo | D22: 2025 | E22: Fatturata | F22: REYIT25-12408 | G22: {=SUMPRODUCT(('Budget Lines - Leonardo'!$F$2:$F$1526=Offers!B22)*('Budget Lines - Leonardo'!$G$2:$G$1526))} -> 114000 | H22: 125775 | I22: =Tabella1[[#This Row],[Importo in offerta]]-Tabella1[[#This Row],[Importo finale]] -> 11775
B23: Leonardo - CRPACK Q4 | C23: Leonardo | D23: 2025 | E23: Fatturata | G23: {=SUMPRODUCT(('Budget Lines - Leonardo'!$F$2:$F$1526=Offers!B23)*('Budget Lines - Leonardo'!$G$2:$G$1526))} -> 108360 | H23: 108360 | I23: =Tabella1[[#This Row],[Importo in offerta]]-Tabella1[[#This Row],[Importo finale]] -> 0
B24: Leonardo - Cortex Antivirus Moodle(QU) | C24: Leonardo | D24: 2025 | E24: Fatturata | F24: REYIT25-12409 | G24: {=SUMPRODUCT(('Budget Lines - Leonardo'!$F$2:$F$1526=Offers!B24)*('Budget Lines - Leonardo'!$G$2:$G$1526))} -> 6895 | H24: 6960 | I24: =Tabella1[[#This Row],[Importo in offerta]]-Tabella1[[#This Row],[Importo finale]] -> 65
B25: Leonardo - Traduzione Moodboard | C25: Leonardo | D25: 2025 | E25: Fatturata | F25: REYIT25-12410 | G25: {=SUMPRODUCT(('Budget Lines - Leonardo'!$F$2:$F$1526=Offers!B25)*('Budget Lines - Leonardo'!$G$2:$G$1526))} -> 17600 | H25: 18060 | I25: =Tabella1[[#This Row],[Importo in offerta]]-Tabella1[[#This Row],[Importo finale]] -> 460
B26: AMS Backend for Frontend and small enhancements | C26: Leonardo | D26: 2025 | E26: Fatturata | F26: REYIT25-09311 | G26: {=SUMPRODUCT(('Budget Lines - Leonardo'!$F$2:$F$1526=Offers!B26)*('Budget Lines - Leonardo'!$G$2:$G$1526))} -> 0 | I26: =Tabella1[[#This Row],[Importo in offerta]]-Tabella1[[#This Row],[Importo finale]] -> 0
B27: AMS Frontend and small enhancements | C27: Leonardo | D27: 2025 | E27: Fatturata | F27: REYIT25-09310 | G27: {=SUMPRODUCT(('Budget Lines - Leonardo'!$F$2:$F$1526=Offers!B27)*('Budget Lines - Leonardo'!$G$2:$G$1526))} -> 0 | I27: =Tabella1[[#This Row],[Importo in offerta]]-Tabella1[[#This Row],[Importo finale]] -> 0
B28: Intranet - AMS ITO CoreMedia Intranet and small enhancements | C28: Intranet | D28: 2025 | E28: Fatturata | F28: REYIT25-06562 | G28: {=SUMPRODUCT(('Budget Lines - Leonardo'!$F$2:$F$1526=Offers!B28)*('Budget Lines - Leonardo'!$G$2:$G$1526))} -> 0 | I28: =Tabella1[[#This Row],[Importo in offerta]]-Tabella1[[#This Row],[Importo finale]] -> 0
B29: Intranet - AMS ITO Intranet and small enhancements | C29: Intranet | D29: 2025 | E29: Fatturata | F29: REYIT25-06569 | G29: {=SUMPRODUCT(('Budget Lines - Leonardo'!$F$2:$F$1526=Offers!B29)*('Budget Lines - Leonardo'!$G$2:$G$1526))} -> 0 | I29: =Tabella1[[#This Row],[Importo in offerta]]-Tabella1[[#This Row],[Importo finale]] -> 0
B30: Intranet - AMS ITO Novelties and small enhancements | C30: Leonardo | D30: 2025 | E30: Fatturata | F30: REYIT25-06575 | G30: {=SUMPRODUCT(('Budget Lines - Leonardo'!$F$2:$F$1526=Offers!B30)*('Budget Lines - Leonardo'!$G$2:$G$1526))} -> 0 | I30: =Tabella1[[#This Row],[Importo in offerta]]-Tabella1[[#This Row],[Importo finale]] -> 0
B31: Intranet - Licenza TT | C31: Intranet | D31: 2025 | E31: Fatturata | G31: {=SUMPRODUCT(('Budget Lines - Leonardo'!$F$2:$F$1526=Offers!B31)*('Budget Lines - Leonardo'!$G$2:$G$1526))} -> 0 | I31: =Tabella1[[#This Row],[Importo in offerta]]-Tabella1[[#This Row],[Importo finale]] -> 0
B32: Intranet - OEL Intranet AMS and small enhancements | C32: Intranet | D32: 2025 | E32: Fatturata | F32: REYIT25-06538 | G32: {=SUMPRODUCT(('Budget Lines - Leonardo'!$F$2:$F$1526=Offers!B32)*('Budget Lines - Leonardo'!$G$2:$G$1526))} -> 0 | I32: =Tabella1[[#This Row],[Importo in offerta]]-Tabella1[[#This Row],[Importo finale]] -> 0
B33: Leonardo - CR PACK CMS R1.2026 | C33: Leonardo | D33: 2026 | E33: Inviata | F33: REYIT26-02354 | G33: {=SUMPRODUCT(('Budget Lines - Leonardo'!$F$2:$F$1526=Offers!B33)*('Budget Lines - Leonardo'!$G$2:$G$1526))} -> 0 | I33: =Tabella1[[#This Row],[Importo in offerta]]-Tabella1[[#This Row],[Importo finale]] -> 0
B34: Leonardo - Massive_Retraining | C34: Leonardo | D34: 2026 | E34: Inviata | F34: REYIT26-02352 | G34: {=SUMPRODUCT(('Budget Lines - Leonardo'!$F$2:$F$1526=Offers!B34)*('Budget Lines - Leonardo'!$G$2:$G$1526))} -> 17330 | H34: 18060 | I34: =Tabella1[[#This Row],[Importo in offerta]]-Tabella1[[#This Row],[Importo finale]] -> 730
B35: Leonardo - Manager Assignment Extention | C35: Leonardo | D35: 2026 | E35: Inviata | F35: REYIT26-02349 | G35: {=SUMPRODUCT(('Budget Lines - Leonardo'!$F$2:$F$1526=Offers!B35)*('Budget Lines - Leonardo'!$G$2:$G$1526))} -> 17760 | H35: 18490 | I35: =Tabella1[[#This Row],[Importo in offerta]]-Tabella1[[#This Row],[Importo finale]] -> 730
B36: Leonardo - Migration to NAM | C36: Leonardo | D36: 2026 | E36: Inviata | F36: REYIT26-02348 | G36: {=SUMPRODUCT(('Budget Lines - Leonardo'!$F$2:$F$1526=Offers!B36)*('Budget Lines - Leonardo'!$G$2:$G$1526))} -> 19050 | H36: 19780 | I36: =Tabella1[[#This Row],[Importo in offerta]]-Tabella1[[#This Row],[Importo finale]] -> 730
B37: Leonardo - Coins Deprecation | C37: Leonardo | D37: 2026 | E37: Inviata | F37: REYIT26-02346 | G37: {=SUMPRODUCT(('Budget Lines - Leonardo'!$F$2:$F$1526=Offers!B37)*('Budget Lines - Leonardo'!$G$2:$G$1526))} -> 25930 | H37: 26660 | I37: =Tabella1[[#This Row],[Importo in offerta]]-Tabella1[[#This Row],[Importo finale]] -> 730
B38: Leonardo - CR PACK Q1 | C38: Leonardo | D38: 2026 | E38: Inviata | F38: REYIT26-02356 | G38: {=SUMPRODUCT(('Budget Lines - Leonardo'!$F$2:$F$1526=Offers!B38)*('Budget Lines - Leonardo'!$G$2:$G$1526))} -> 0 | H38: 119970 | I38: =Tabella1[[#This Row],[Importo in offerta]]-Tabella1[[#This Row],[Importo finale]] -> 119970
B39: Intranet - Evolutions Q1 | C39: Intranet | D39: 2026 | E39: Inviata | F39: REYIT26-02454 | G39: {=SUMPRODUCT(('Budget Lines - Intranet'!$F$2:$F$1531=Offers!B39)*('Budget Lines - Intranet'!$G$2:$G$1531))} -> 12900 | H39: 13050 | I39: =Tabella1[[#This Row],[Importo in offerta]]-Tabella1[[#This Row],[Importo finale]] -> 150
B40: W2EL - DevOps Activities | C40: Altro | D40: 2026 | E40: Inviata | F40: REYIT26-02512 | G40: {=SUMPRODUCT(('Budget Lines - Leonardo'!$F$2:$F$1526=Offers!B40)*('Budget Lines - Leonardo'!$G$2:$G$1526))} -> 17200 | H40: 17450 | I40: =Tabella1[[#This Row],[Importo in offerta]]-Tabella1[[#This Row],[Importo finale]] -> 250
B41: Back End Developer for EHR Team | C41: Altro | D41: 2026 | E41: Inviata | F41: REYIT26-02344 | G41: {=SUMPRODUCT(('Budget Lines - Leonardo'!$F$2:$F$1526=Offers!B41)*('Budget Lines - Leonardo'!$G$2:$G$1526))} -> 0 | I41: =Tabella1[[#This Row],[Importo in offerta]]-Tabella1[[#This Row],[Importo finale]] -> 0
B42: Leonardo - Program Simplification New UI | C42: Leonardo | D42: 2026 | E42: Inviata | F42: REYIT26-03330 | G42: {=SUMPRODUCT(('Budget Lines - Leonardo'!$F$2:$F$1526=Offers!B42)*('Budget Lines - Leonardo'!$G$2:$G$1526))} -> 45270 | H42: 45400 | I42: =Tabella1[[#This Row],[Importo in offerta]]-Tabella1[[#This Row],[Importo finale]] -> 130
B43: Leonardo - Translator-J CMS | C43: Leonardo | D43: 2026 | E43: Inviata | F43: REYIT26-03331 | G43: {=SUMPRODUCT(('Budget Lines - Leonardo'!$F$2:$F$1526=Offers!B43)*('Budget Lines - Leonardo'!$G$2:$G$1526))} -> 43000 | H43: 43000 | I43: =Tabella1[[#This Row],[Importo in offerta]]-Tabella1[[#This Row],[Importo finale]] -> 0
B44: Leonardo - Log Activation W1 | C44: Leonardo | D44: 2026 | E44: Inviata | F44: REYIT26-03332 | G44: {=SUMPRODUCT(('Budget Lines - Leonardo'!$F$2:$F$1526=Offers!B44)*('Budget Lines - Leonardo'!$G$2:$G$1526))} -> 37840 | H44: 38150 | I44: =Tabella1[[#This Row],[Importo in offerta]]-Tabella1[[#This Row],[Importo finale]] -> 310
B45: Leonardo - Homepage on CMS (CAE to CAAS) | C45: Leonardo | D45: 2026 | E45: Inviata | F45: REYIT26-07179 | G45: {=SUMPRODUCT(('Budget Lines - Leonardo'!$F$2:$F$1526=Offers!B45)*('Budget Lines - Leonardo'!$G$2:$G$1526))} -> 0 | H45: 46500 | I45: =Tabella1[[#This Row],[Importo in offerta]]-Tabella1[[#This Row],[Importo finale]] -> 46500
B46: AMS VIVA App [Mobile] | C46: VIVA | D46: 2026 | F46: REYIT26-03322 | G46: {=SUMPRODUCT(('Budget Lines - VIVA'!$F$2:$F$1536=Offers!B46)*('Budget Lines - VIVA'!$G$2:$G$1536))} -> 25000 | H46: 25000 | I46: =Tabella1[[#This Row],[Importo in offerta]]-Tabella1[[#This Row],[Importo finale]] -> 0
B47: AMS VIVA App [Backend] | C47: VIVA | D47: 2026 | F47: REYIT26-03323 | G47: {=SUMPRODUCT(('Budget Lines - VIVA'!$F$2:$F$1536=Offers!B47)*('Budget Lines - VIVA'!$G$2:$G$1536))} -> 25000 | H47: 25000 | I47: =Tabella1[[#This Row],[Importo in offerta]]-Tabella1[[#This Row],[Importo finale]] -> 0
B48: AMS VIVA App [DevOps] | C48: VIVA | D48: 2026 | F48: REYIT26-03324 | G48: {=SUMPRODUCT(('Budget Lines - VIVA'!$F$2:$F$1536=Offers!B48)*('Budget Lines - VIVA'!$G$2:$G$1536))} -> 25000 | H48: 25000 | I48: =Tabella1[[#This Row],[Importo in offerta]]-Tabella1[[#This Row],[Importo finale]] -> 0
...

Sheet Activities - Leonardo
A1: ID | B1: Attività | C1: Data iniziativa | D1: RELEASE | E1: Ref. Luxottica | F1: Codice REY | G1: Ref. Stima | H1: Stato | I1: Importo | J1: Importo scontato | K1: Sconto % | L1: B2B - CTIA | M1: FE | N1: CMS | O1: BFF | P1: CTIA - DevOps | Q1: Altri team | R1: Riferimento stima | S1: Old stima
B2: Leonardo - Teams New API | C2: 45413 | D2: 45536 | E2: Carlo Stella | F2: REYIT24-13133 | G2: Verzeletti | H2: 5.b Fatturato | I2: =SUM(L2:P2) -> 6450 | L2: =15*430 -> 6450 | R2: https://reply.sharepoint.com/:x:/r/sites/University-stimeepiani/Shared%20Documents/stime%20e%20piani/IN%20STIMA/Leonardo%20-%20Teams%20New%20API.xlsx?d=wb726c7a9fcd147efac8942fc1bef57d2&csf=1&web=1&e=rmmC5i
B3: Leonardo - Test nuovi ambienti | C3: 45474 | D3: oct-24 | E3: Carlo Stella | F3: REYIT24-13133 | G3: Verzeletti | H3: 5.b Fatturato | I3: =SUM(L3:P3) -> 24940 | L3: =52*430 -> 22360 | M3: =6*430 -> 2580 | R3: https://reply.sharepoint.com/:x:/r/sites/University-stimeepiani/_layouts/15/Doc.aspx?sourcedoc=%7B16BF94AF-CE1B-4CA9-B616-06DE393A745E%7D&file=ELL-3813%20Leonardo%20-%20Test%20nuovi%20ambienti.xlsx&action=default&mobileredirect=true
B4: Leonardo - Elastic POC | C4: 45627 | E4: Carlo Stella | F4: REYIT24-13133 | G4: Furci | H4: 5.b Fatturato | I4: =SUM(L4:Q4) -> 14190 | L4: =8*430 -> 3440 | Q4: =25*430 -> 10750 | R4: https://reply.sharepoint.com/:x:/r/sites/University-stimeepiani/_layouts/15/Doc2.aspx?action=edit&sourcedoc=%7B814f46cf-623e-4a2b-aba7-0e848fadedd0%7D&wdOrigin=TEAMS-MAGLEV.teamsSdk_ns.rwc&wdExp=TEAMS-TREATMENT&wdhostclicktime=1734018141064&web=1&ovuser=b00367e2-193a-4f48-94de-7245d45c0947%2Cm.verzeletti%40reply.it&clickparams=eyJBcHBOYW1lIjoiVGVhbXMtRGVza3RvcCIsIkFwcFZlcnNpb24iOiI1MC8yNDExMDExNTcyMiIsIkhhc0ZlZGVyYXRlZFVzZXIiOmZhbHNlfQ%3D%3D
B5: Leonardo - Video Tracking Dynamic Timing | C5: 45566 | D5: 45597 | E5: Carlo Stella | F5: REYIT24-10651 | G5: Verzeletti | H5: 5.b Fatturato | I5: =430*7 -> 3010 | L5: =I5-M5 -> 2365 | M5: 645 | R5: ELL-2999 - Leonardo - Video Tracking Dynamic Timing.xlsx
B6: Leonardo - Login Optimization | C6: 45566 | D6: 45689 | E6: Carlo Stella | F6: REYIT24-10651 | G6: Verzeletti | H6: 5.b Fatturato | I6: =SUM(L6:Q6) -> 22145 | L6: =51.5*430-1500 -> 20645 | Q6: 1500 | R6: https://reply.sharepoint.com/:x:/r/sites/University-stimeepiani/_layouts/15/Doc2.aspx?action=edit&sourcedoc=%7B75f8fafa-67eb-4f5c-b2fd-7df03b5fd4cd%7D&wdOrigin=TEAMS-MAGLEV.teamsSdk_ns.rwc&wdExp=TEAMS-TREATMENT&wdhostclicktime=1729245012865&web=1 | S6: https://reply.sharepoint.com/:x:/r/sites/University-stimeepiani/_layouts/15/doc2.aspx?sourcedoc=%7B2E99CEA4-4A54-4123-B9C7-24470762B6B1%7D&file=Leonardo%20-%20Login%20Optimization%20v2.xlsx&action=default&mobileredirect=true
B7: Leonardo - Reperibilità | C7: 45566 | D7: oct-24 | E7: Carlo Stella | F7: REYIT24-10651 | G7: Verzeletti | H7: 5.b Fatturato | I7: 2800 | L7: =1500+50 -> 1550 | M7: 700 | Q7: 550
B8: Leonardo - Stress Tests Session | C8: 45597 | D8: 45627 | E8: Carlo Stella | F8: REYIT24-10651 | G8: Verzeletti | H8: 5.b Fatturato | I8: =SUM(L8:Q8) -> 4730 | L8: =6*430+150 -> 2730 | Q8: 2000 | R8: https://reply.sharepoint.com/:x:/r/sites/University-stimeepiani/_layouts/15/Doc2.aspx?action=edit&sourcedoc=%7Bd61bf720-526c-47ff-a425-806446bfc7c3%7D&wdOrigin=TEAMS-MAGLEV.teamsSdk_ns.rwc&wdExp=TEAMS-TREATMENT&wdhostclicktime=1732529183444&web=1
B9: Leonardo - Collection wave 3 - pt2 | C9: 45292 | E9: Carlo Stella | F9: REYIT24-10650 | G9: Furci | H9: 5. Ordine ricevuto | I9: 28230 | L9: 20000 | M9: 8230 | R9: https://reply.sharepoint.com/:x:/r/sites/University-stimeepiani/Shared%20Documents/stime%20e%20piani/IN%20STIMA/Leonardo%20-%20Collection%20Wave%203.xlsx?d=w3dcb3df06bfb4c2e99daa1b9fba6c7d3&csf=1&web=1&e=vRtHtJ
B10: Leonardo - CR Team CMS Luglio | C10: 45474 | D10: 45597 | E10: Carlo Stella | F10: REYIT24-10650 | G10: Verzeletti | H10: 5. Ordine ricevuto | I10: =SUM(L10:P10) -> 11180 | L10: - | N10: 11180 | R10: Leonardo - Team CMS Luglio.xlsx
B11: Leonardo - CR Team CMS Dicembre 24 | C11: 45597 | D11: 45627 | E11: Carlo Stella | F11: REYIT24-10650 | G11: Verzeletti | H11: 5. Ordine ricevuto | I11: =SUM(L11:P11) -> 2150 | N11: =5*430 -> 2150 | R11: https://reply.sharepoint.com/:x:/r/sites/University-stimeepiani/_layouts/15/Doc2.aspx?action=edit&sourcedoc=%7B16c4efce-72c6-4838-9220-4e93f8ab38fb%7D&wdOrigin=TEAMS-MAGLEV.teamsSdk_ns.rwc&wdExp=TEAMS-TREATMENT&wdhostclicktime=1730826335774&web=1
B12: Leonardo - Teams / Vimeo & LS / VC | C12: 45536 | D12: 45717 | E12: Carlo Stella | F12: REYIT25-02204 | G12: Verzeletti | H12: 4.a Offerta inviata a ufficio acquisti | I12: =SUM(L12:P12) -> 15050 | L12: =16*430 -> 6880 | M12: =19*430 -> 8170 | R12: ELL-3950 - Leonardo - Teams Vimeo.xlsx
B13: Leonardo - Audit 24 - Approval Step | C13: 45658 | D13: 45717 | E13: Carlo Stella | F13: REYIT25-02338 | G13: Verzeletti | H13: 5.b Fatturato | I13: =SUM(L13:Q13) -> 8385 | L13: =2*430 + 2*430 -> 1720 | Q13: =15.5*430 -> 6665 | R13: ELL-4208 - Leonardo - Audit 24 - Approval Step.xlsx
B14: Leonardo - Audit 24 - Data Anonymization | C14: 45658 | D14: 45717 | E14: Carlo Stella | F14: REYIT25-02338 | G14: Verzeletti | H14: 5.b Fatturato | I14: =SUM(L14:Q14) -> 8600 | L14: =20*430 -> 8600 | R14: ELL-4208 - Leonardo - Audit 24 - Data Anonimization.xlsx
B15: Leonardo - CR TEAM CMS Marzo 2025 | C15: 45627 | D15: 45717 | E15: Carlo Stella | F15: REYIT25-02491 | G15: Verzeletti | H15: 5.b Fatturato | I15: =SUM(L15:P15) -> 4730 | L15: =1*430 -> 430 | N15: =10*430 -> 4300 | R15: Leonardo - Team CMS CR Marzo 2025.xlsx
B16: Leonardo - Modulo Experts CMS | C16: 45658 | D16: 45717 | E16: Carlo Stella | F16: REYIT25-02491 | G16: Verzeletti | H16: 5.b Fatturato | I16: =SUM(L16:Q16) -> 24710 | L16: =(8+3)*430 -> 4730 | M16: =23*420 -> 9660 | N16: =24*430 -> 10320 | R16: ELL-4401 - Leonardo CMS Expert Module.xlsx
B17: Leonardo - Onboarding Semplification | C17: 45474 | D17: 45717 | E17: Carlo Stella | F17: REYIT24-13130 | G17: Verzeletti | H17: 5.b Fatturato | I17: 37410 | L17: =(27+24.5)*430 -> 22145 | M17: =I17-L17 -> 15265 | R17: ELL-3681 - Leonardo - OB Semplification_v2.xlsx
B18: Leonardo - Onboarding Semplification - pt2 | C18: 45474 | D18: 45717 | E18: Carlo Stella | F18: REYIT25-02607 | G18: Verzeletti | H18: 4.a Offerta inviata a ufficio acquisti | I18: 7310 | M18: 7310 | R18: ELL-3681 - Leonardo - OB Semplification_v2.xlsx
B19: Leonardo - Manager Assignment | C19: 45444 | D19: 45689 | E19: Carlo Stella | F19: REYIT25-02791 | G19: Verzeletti | H19: 4.a Offerta inviata a ufficio acquisti | I19: =SUM(L19:P19) -> 66970 | L19: =104*430-10000 -> 34720 | M19: 32250 | R19: https://reply.sharepoint.com/:x:/r/sites/University-stimeepiani/_layouts/15/Doc.aspx?sourcedoc=%7B1936F972-96D1-477C-8E9D-A3D5E4C93F60%7D&file=Leonardo%20template.xlsx&action=default&mobileredirect=true&wdsle=0
B20: Leonardo - LP Visibility Optional | C20: 45597 | D20: 45658 | E20: Carlo Stella | F20: REYIT25-02790 | G20: Verzeletti | H20: 4.a Offerta inviata a ufficio acquisti | I20: =SUM(L20:P20) -> 24940 | L20: =45.5*430 -> 19565 | M20: =12.5*430 -> 5375 | R20: https://reply.sharepoint.com/:x:/r/sites/University-stimeepiani/_layouts/15/Doc2.aspx?action=edit&sourcedoc=%7B932b8af2-56f7-4391-8de5-8b69b535aad8%7D&wdOrigin=TEAMS-MAGLEV.teamsSdk_ns.rwc&wdExp=TEAMS-TREATMENT&wdhostclicktime=1733131932576&web=1
B21: Leonardo - Content Language Management | C21: 45444 | D21: 45717 | E21: Carlo Stella | F21: REYIT25-02908 | G21: Verzeletti | H21: 2. Stima approvata | I21: =SUM(L21:P21) -> 47300 | L21: =(24+37.5)*430 -> 26445 | M21: 20855 | R21: ELL-3651 - Leonardo - Content Language Management.xlsx
B22: Leonardo - Rimodulazione architettura BFF | C22: 45474 | D22: 45748 | E22: Carlo Stella | F22: REYIT25-02969 | G22: Verzeletti | H22: 2. Stima approvata | I22: =SUM(L22:Q22) -> 66220 | L22: =139*430 -> 59770 | Q22: =15*430 -> 6450 | R22: https://reply.sharepoint.com/:x:/r/sites/University-stimeepiani/Shared%20Documents/stime%20e%20piani/IN%20STIMA/ELL-3757%20-%20Leonardo%20-%20Rimodulazione%20architettura%20BFF.xlsx?d=w57ecd37669794a6889c230e457b4c992&csf=1&web=1&e=uUHLh1
B23: Leonardo - Async Loading Manager Assignment | C23: 45627 | D23: 45689 | E23: Carlo Stella | F23: REYIT25-02909 | G23: Verzeletti | H23: 5. Ordine ricevuto | I23: =SUM(L23:P23) -> 4730 | L23: =9*430 -> 3870 | M23: =2*430 -> 860 | R23: Leonardo - Async Loading Manager Assignment.xlsx
B24: LUX - Catalog Opt. - ph 2 - Catalog Refactorization | C24: 45017 | E24: Carlo Stella | F24: REYIT25-02909 | G24: Furci | H24: 2. Stima approvata | I24: 17830
B25: Leonardo - Automatic Enrollment | C25: 45658 | D25: 45748 | E25: Carlo Stella | F25: REYIT25-03469 | G25: Verzeletti | H25: 5. Ordine ricevuto | I25: =SUM(L25:Q25) -> 18060 | L25: =15*430 -> 6450 | M25: =27*430 -> 11610 | R25: https://reply.sharepoint.com/:x:/r/sites/University-stimeepiani/_layouts/15/Doc2.aspx?action=edit&sourcedoc=%7B8ab7003c-b42e-4054-a7b9-bf9159d9ea4b%7D&wdOrigin=TEAMS-MAGLEV.teamsSdk_ns.rwc&wdExp=TEAMS-TREATMENT&wdhostclicktime=1736873121548&web=1&clickparams=eyJBcHBOYW1lIjoiVGVhbXMtRGVza3RvcCIsIkFwcFZlcnNpb24iOiI1MC8yNDEyMDEwMDIxMyJ9
B26: Leonardo - Stress Tests and Rollout Manag Assign Cap100 | C26: 45772 | D26: 45748 | E26: Carlo Stella | G26: Verzeletti | H26: 5. Ordine ricevuto | I26: =SUM(L26:P26) -> 4300 | L26: =10*430 -> 4300 | R26: https://reply.sharepoint.com/:x:/r/sites/University-stimeepiani/_layouts/15/Doc2.aspx?action=edit&sourcedoc=%7B04620e5a-ee7e-4e8b-abce-06ae10e09ecc%7D&wdOrigin=TEAMS-MAGLEV.teamsSdk_ns.rwc&wdExp=TEAMS-TREATMENT&wdhostclicktime=1741714743184&web=1&ovuser=b00367e2-193a-4f48-94de-7245d45c0947%2Cm.verzeletti%40reply.it&clickparams=eyJBcHBOYW1lIjoiVGVhbXMtRGVza3RvcCIsIkFwcFZlcnNpb24iOiI1MC8yNTAyMTQwMDkxMiIsIkhhc0ZlZGVyYXRlZFVzZXIiOmZhbHNlfQ%3D%3D
B27: Leonardo - Automation Localization Workflows CMS Latest Collection | C27: 45689 | D27: 45809 | E27: Carlo Stella | F27: REYIT25-04636 | G27: Verzeletti | H27: 5. Ordine ricevuto | I27: =SUM(L27:P27) -> 25800 | N27: =60*430 -> 25800 | R27: ELL-4516 - Leonardo - Automatic Flow Latest Collection.xlsx
B28: Leonardo - CR PACK CMS Apr 25 | C28: 45741 | D28: 45809 | E28: Carlo Stella | F28: REYIT25-04636 | G28: Verzeletti | H28: 5. Ordine ricevuto | I28: =SUM(L28:P28) -> 6020 | L28: 430 | N28: =13*430 -> 5590 | R28: Leonardo - CR PACK CMS - LEON-10086.xlsx
B29: Leonardo - Hypercare Upgrade Moodle | C29: 45772 | D29: 45778 | E29: Carlo Stella | F29: REYIT25-04636 | G29: Losi | H29: 5. Ordine ricevuto | I29: 2800 | L29: 1340 | M29: 600 | Q29: 860 | R29: Thread Mail
B30: Leonardo - Refactor PDP | C30: 45566 | D30: 45901 | E30: Carlo Stella | F30: REYIT25-07583 | G30: Verzeletti | H30: 5. Ordine ricevuto | I30: =SUM(L30:P30) -> 22790 | L30: =16*430 -> 6880 | M30: =37*430 -> 15910 | R30: https://reply.sharepoint.com/:x:/r/sites/University-stimeepiani/_layouts/15/Doc.aspx?sourcedoc=%7BE9F156F3-E429-4EAD-A529-D6AA08BD6BF2%7D&file=Leonardo%20-%20PDP%20Refactor.xlsx&action=default&mobileredirect=true
B31: Leonardo - CMS Migration to ONE | C31: 45597 | D31: 45931 | E31: Carlo Stella | G31: Verzeletti | H31: 2. Stima approvata | I31: =SUM(L31:P31) -> 95460 | L31: =89*430 -> 38270 | M31: =43*430 -> 18490 | N31: =90*430 -> 38700 | R31: ELL-4114 Leonardo - CMS Migration to ONE_v1.xlsx | S31: https://reply.sharepoint.com/:x:/r/sites/University-stimeepiani/_layouts/15/Doc2.aspx?action=edit&sourcedoc=%7Bcee75ede-27c1-464e-b15b-8f9d9a1bc9a3%7D&wdOrigin=TEAMS-MAGLEV.teamsSdk_ns.rwc&wdExp=TEAMS-TREATMENT&wdhostclicktime=1743160304913&web=1 | T31: https://reply.sharepoint.com/:x:/r/sites/University-stimeepiani/_layouts/15/Doc2.aspx?action=edit&sourcedoc=%7Bec12c297-6780-4e58-8587-9fee084c59f3%7D&wdOrigin=TEAMS-MAGLEV.teamsSdk_ns.rwc&wdExp=TEAMS-TREATMENT&wdhostclicktime=1743160307271&web=1
B32: Leonardo - Upgrade Moodle | C32: 45597 | D32: 45778 | E32: Carlo Stella | G32: Verzeletti | H32: 2. Stima approvata | I32: =SUM(L32:Q32) -> 50310 | L32: =81.5*430+215 -> 35260 | M32: =17*430 -> 7310 | Q32: =(10.5+8)*430-215 -> 7740 | R32: https://reply.sharepoint.com/:x:/r/sites/University-stimeepiani/_layouts/15/Doc2.aspx?action=edit&sourcedoc=%7Bf14edfbd-1bf2-46eb-bca4-4aeded31d623%7D&wdOrigin=TEAMS-MAGLEV.teamsSdk_ns.rwc&wdExp=TEAMS-TREATMENT&wdhostclicktime=1741792439279&web=1
B33: Quality | I33: 485685
B34: Leonardo - C560360L Flusso di traduzione Moodboard | C34: 45925 | E34: Carlo Stella | G34: Orlandi | H34: 2. Stima approvata | I34: =20*430 -> 8600 | N34: =20*430 -> 8600 | R34: https://reply.sharepoint.com/:x:/r/sites/University-stimeepiani/Shared%20Documents/stime%20e%20piani/IN%20STIMA/C560360L%20-%20flusso%20di%20traduzione%20Moodboard.xlsx?d=w93cd64a820e1487284151d9a4106e678&csf=1&web=1&e=8dzoNh
B35: Leonardo - Cortex Antivirus Moodle(QU) | C35: 45955 | D35: 45931 | E35: Carlo Stella | G35: Verzeletti | H35: 2. Stima approvata | I35: =SUM(L35:Q35) -> 3010 | Q35: =7*430 -> 3010 | R35: https://reply.sharepoint.com/:x:/r/sites/University-stimeepiani/_layouts/15/Doc2.aspx?action=edit&sourcedoc=%7B3bad514a-29ef-4ee1-b32d-eed045da203c%7D&wdOrigin=TEAMS-MAGLEV.teamsSdk_ns.rwc&wdExp=TEAMS-TREATMENT&wdhostclicktime=1759852920062&web=1
B36: Leonardo - Migration to NAM | C36: 45863 | D36: 46054 | E36: Carlo Stella | F36: REYIT26-02348 | G36: Verzeletti | H36: 4. Offerta Inviata IT | I36: 12900 | L36: 12900 | R36: ELL-4912 - Leonardo - NAM Integration.xlsx
B37: Leonardo - Stress Test NAM Integration | D37: 46054 | E37: Carlo Stella | F37: REYIT26-02348 | G37: Verzeletti | H37: 4. Offerta Inviata IT | I37: 2150 | L37: 430 | P37: 1720 | R37: https://reply.sharepoint.com/:x:/r/sites/University-stimeepiani/_layouts/15/Doc.aspx?sourcedoc=%7Bbf351f28-6bb8-49a2-88d8-ce531951a605%7D&action=edit&wdPreviousSession=2bf705f4-2fee-60e7-bfe1-098e69628046
B38: Leonardo - Massive Retraining | C38: 45925 | D38: 46023 | E38: Carlo Stella | F38: REYIT26-02352 | G38: Verzeletti | H38: 4. Offerta Inviata IT | I38: 13330 | L38: 10110 | M38: 1720 | Q38: 1500 | R38: ELL-5067 - Leonardo - Massive Retraining.xlsx
B39: Leonardo - Manager Assignment Estensione | C39: 45925 | D39: 46054 | E39: Carlo Stella | F39: REYIT26-02349 | G39: Verzeletti | H39: 4. Offerta Inviata IT | I39: 13760 | L39: 9890 | M39: 3870 | R39: ELL-4940 - Leonardo - Manager Assign Extension.xlsx
B40: Leonardo - Coins Deprecation | C40: 45809 | D40: 46054 | E40: Carlo Stella | F40: REYIT26-02346 | G40: Verzeletti | H40: 4. Offerta Inviata IT | I40: 21930 | L40: 15910 | M40: 6020 | Q40: 0 | R40: https://reply.sharepoint.com/:x:/r/sites/University-stimeepiani/Shared%20Documents/stime%20e%20piani/IN%20STIMA/Leonardo%20-%20COIN%20Deprecation.xlsx?d=wa1432a63428c4d61b69aa89e38efef47&csf=1&web=1&e=6dh914
...

Sheet Budget Lines - Leonardo
A1: ID | B1: Nome | C1: Activities | D1: Stato | E1: Commessa | F1: Offers | G1: Importo | H1: Colonna1 | I1: Colonna2
C2: Leonardo - Teams New API | D2: Inserita | E2: LUXO-BLUEIT-22-2-75 - Leonardo 2024 | F2: Leonardo - Elastic POC and stress/performance testing | G2: 6450
C3: Leonardo - Test nuovi ambienti | D3: Inserita | E3: LUXO-BLUEIT-22-2-75 - Leonardo 2024 | F3: Leonardo - Elastic POC and stress/performance testing | G3: 22360
B4: 03Elastic POC | C4: Leonardo - Elastic POC | D4: Inserita | E4: LUXO-BLUEIT-22-2-90 - Leonardo 2025 | F4: Leonardo - Elastic POC and stress/performance testing | G4: 3440
C5: Leonardo - Test nuovi ambienti | D5: Inserita | E5: XXX-XXX-XTECH - | F5: Leonardo - Elastic POC and stress/performance testing | G5: 2580
C6: Leonardo - Elastic POC | D6: Inserita | E6: XXX-MCI-ITO - | F6: Leonardo - Elastic POC and stress/performance testing | G6: 10750
C7: Leonardo - Video Tracking Dynamic Timing | D7: Inserita | E7: LUXO-BLUEIT-22-2-75 - Leonardo 2024 | F7: Leonardo - Login Optimization | G7: 2365
C8: Leonardo - Video Tracking Dynamic Timing | D8: Inserita | E8: XXX-XXX-XTECH - | F8: Leonardo - Login Optimization | G8: 645
C9: Leonardo - Login Optimization | D9: Inserita | E9: LUXO-BLUEIT-22-2-75 - Leonardo 2024 | F9: Leonardo - Login Optimization | G9: 9755
C10: Leonardo - Login Optimization | D10: Inserita | E10: LUXO-BLUEIT-22-2-78 - AM Leonardo 2024 | F10: Leonardo - Login Optimization | G10: 1500
C11: Leonardo - Login Optimization | D11: Inserita | E11: LUXO-BLUEIT-22-2-81 - Leonardo 2024 - Formazione | F11: Leonardo - Login Optimization | G11: 1150
B12: 04Login optimization | C12: Leonardo - Login Optimization | D12: Inserita | E12: LUXO-BLUEIT-22-2-90 - Leonardo 2025 | F12: Leonardo - Login Optimization | G12: 8240
C13: Leonardo - Login Optimization | D13: Inserita | E13: XXX-DPM-ITO - | F13: Leonardo - Login Optimization | G13: 1500
C14: Leonardo - Reperibilità | D14: Inserita | E14: LUXO-BLUEIT-22-2-78 - AM Leonardo 2024 | F14: Leonardo - Login Optimization | G14: 500
C15: Leonardo - Reperibilità | D15: Inserita | E15: LUXO-BLUEIT-22-2-81 - Leonardo 2024 - Formazione | F15: Leonardo - Login Optimization | G15: 1050
C16: Leonardo - Reperibilità | D16: Inserita | E16: XXX-MCI-ITO - | F16: Leonardo - Login Optimization | G16: 550
C17: Leonardo - Reperibilità | D17: Inserita | E17: XXX-XXX-XTECH - | F17: Leonardo - Login Optimization | G17: 700
B18: 05Stresstest q4 | C18: Leonardo - Stress Tests Session | D18: Inserita | E18: LUXO-BLUEIT-22-2-90 - Leonardo 2025 | F18: Leonardo - Login Optimization | G18: 2730
C19: Leonardo - Stress Tests Session | D19: Inserita | E19: XXX-DPM-ITO - | F19: Leonardo - Login Optimization | G19: 2000
C20: ////modifica puntamento | D20: Inserita | E20: XXX-XXX-WDWP - | F20: Leonardo - Login Optimization | G20: 2150
C21: ////traduttore ai | D21: Inserita | E21: XXX-XXX-WDWP - | F21: Leonardo - Login Optimization | G21: 7310
C22: Leonardo - Collection wave 3 - pt2 | D22: Inserita | E22: LUXO-BLUEIT-22-2-75 - Leonardo 2024 | F22: Leonardo - CMS new Pages implementation | G22: 20000
C23: Leonardo - Collection wave 3 - pt2 | D23: Inserita | E23: XXX-XXX-XTECH - | F23: Leonardo - CMS new Pages implementation | G23: 8230
C24: Leonardo - CR Team CMS Dicembre 24 | D24: Inserita | E24: XXX-XXX-WDWP - | F24: Leonardo - CMS new Pages implementation | G24: 2150
C25: Leonardo - CR Team CMS Luglio | D25: Inserita | E25: XXX-XXX-WDWP - | F25: Leonardo - CMS new Pages implementation | G25: 11180
B26: 06Teams / Vimeo & LS / VC | C26: Leonardo - Teams / Vimeo & LS / VC | D26: Inserita | E26: LUXO-BLUEIT-22-2-90 - Leonardo 2025 | F26: Leonardo - Teams / Vimeo & LS / VC | G26: 6880
B27: 7 Teams Vimeo | C27: Leonardo - Teams / Vimeo & LS / VC | D27: Inserita | E27: LUXO-BLUEIT-22-2-89 - Leonardo - Fe Support 2025 | F27: Leonardo - Teams / Vimeo & LS / VC | G27: 8170
B28: 06Teams / Vimeo & LS / VC | C28: Leonardo - Manager Assignment pt2 | D28: Inserita | E28: LUXO-BLUEIT-22-2-90 - Leonardo 2025 | F28: Leonardo - Teams / Vimeo & LS / VC | G28: 10000
B29: 06Teams / Vimeo & LS / VC | C29: Leonardo - CMS New Pages Improvements | D29: Inserita | E29: LUXO-BLUEIT-22-2-90 - Leonardo 2025 | F29: Leonardo - Teams / Vimeo & LS / VC | G29: 670
B30: Login_Optimization | C30: xxxx | D30: Inserita | E30: LUXO-BLUEIT-22-2-103 - Leonardo formazione 2025 | F30: Leonardo - Teams / Vimeo & LS / VC | G30: 510
C31: Leonardo - Audit 24 - Approval Step | D31: Inserita | E31: XXX-MCI-ITO - | F31: Leonardo - Internal Audit | G31: 6665
B32: 07Internal Audit | C32: Leonardo - Audit 24 - Data Anonymization | D32: Inserita | E32: LUXO-BLUEIT-22-2-90 - Leonardo 2025 | F32: Leonardo - Internal Audit | G32: 8600
B33: 07Internal Audit | C33: Leonardo - Audit 24 - Approval Step | D33: Inserita | E33: LUXO-BLUEIT-22-2-90 - Leonardo 2025 | F33: Leonardo - Internal Audit | G33: 1720
C34: Leonardo - CR TEAM CMS Marzo 2025 | D34: Inserita | E34: XXX-XXX-WDWP - | F34: Leornado - CMS Module Expert | G34: 4300
B35: Modulo Experts CMS | C35: Leonardo - CR TEAM CMS Marzo 2025 | D35: Inserita | E35: LUXO-BLUEIT-22-2-103 - Leonardo formazione 2025 | F35: Leornado - CMS Module Expert | G35: 430
B36: Modulo Experts CMS | C36: Leonardo - Modulo Experts CMS | D36: Inserita | E36: LUXO-BLUEIT-22-2-103 - Leonardo formazione 2025 | F36: Leornado - CMS Module Expert | G36: 4730
C37: Leonardo - Modulo Experts CMS | D37: Inserita | E37: XXX-XXX-WDWP - | F37: Leornado - CMS Module Expert | G37: 10320
B38: 4 Modulo Expert | C38: Leonardo - Modulo Experts CMS | D38: Inserita | E38: LUXO-BLUEIT-22-2-89 - Leonardo - Fe Support 2025 | F38: Leornado - CMS Module Expert | G38: 9660
C39: Leonardo - Onboarding Semplification | D39: Inserita | E39: LUXO-BLUEIT-22-2-75 - Leonardo 2024 | F39: Leonardo - Onboarding Semplification | G39: 14910
B40: BASELINE | C40: Leonardo - Onboarding Semplification | D40: Inserita | E40: LUXO-BLUEIT-22-2-90 - Leonardo 2025 | F40: Leonardo - Onboarding Semplification | G40: 7955
...

Sheet app
F3: Leonardo - Coins Deprecation | G3: Inserita | H3: LUXO-BLUEIT-22-2-90 - Leonardo 2025 | I3: Leonardo - Coins Deprecation | J3: 15910 | M3: 47815 | R3: REYIT26-02346 | S3: 4554126129 | T3: Blue-Ecomm | U3: LUXO-BLUEIT-25-75-4 | V3: 25930 | Y3: =V3+V5-16000 -> 11315
F4: Leonardo - Coins Deprecation | G4: Inserita | H4: LUXO-BLUEIT-22-2-109 - Leonardo - Fe Support 2026 | I4: Leonardo - Coins Deprecation | J4: 6020 | M4: 4700
G5: Inserita | I5: Leonardo - Coins Deprecation | J5: 4000 | M5: =M3+M4 -> 52515 | R5: REYIT26-02352 | S5: 4554126127 | T5: Blue-Ecomm | U5: LUXO-BLUEIT-25-75-4 | V5: 1385 | X5: =17330-V5-V8-V6 -> 3054
M6: 25200 | R6: REYIT26-02352 | S6: 4554126127 | T6: Blue-Ecomm | U6: LUXO-BLUEIT-22-2-90 | V6: 11391
E7: REYIT26-02352 | F7: Leonardo - Massive Retraining | G7: Inserita | H7: LUXO-BLUEIT-22-2-107 - Leonardo 2026 | I7: Leonardo - Massive_Retraining | J7: 2300 | L7: 25930 | M7: =M5-M6 -> 27315 | N7: =M7-L7 -> 1385 | R7: REYIT26-02352 | S7: 4554126127 | T7: Blue-Ecomm | U7: LUXO-BLUEIT-22-2-109 | V7: 3054
E8: REYIT26-02352 | F8: Leonardo - Massive Retraining | G8: Inserita | H8: LUXO-BLUEIT-22-2-107 - Leonardo 2026 | I8: Leonardo - Massive_Retraining | J8: 7810 | R8: REYIT26-02352 | S8: 4554126127 | T8: Blue-Ecomm | V8: 1500
E9: REYIT26-02352 | F9: Leonardo - Massive Retraining | G9: Inserita | H9: LUXO-BLUEIT-22-2-109 - Leonardo - Fe Support 2026 | I9: Leonardo - Massive_Retraining | J9: 1720
E10: REYIT26-02352 | F10: Leonardo - Massive Retraining | G10: Da inserire | H10: XXX-DPM-ITO - | I10: Leonardo - Massive_Retraining | J10: 1500 | R10: REYIT26-02349 | S10: 4554126126 | T10: Blue-Ecomm | V10: =J14+J16 -> 13890
G11: Inserita | I11: Leonardo - Massive_Retraining | J11: 4000 | M11: 158410 | R11: REYIT26-02349 | S11: 4554126126 | T11: Blue-Ecomm | U11: LUXO-BLUEIT-22-2-107 | V11: =J15 -> 3870
M12: 130000
R13: REYIT26-02348 | S13: 4554126125 | T13: Blue-Ecomm | U13: LUXO-BLUEIT-22-2-107 | V13: 19050
F14: Leonardo - Manager Assignment Estensione | G14: Inserita | H14: LUXO-BLUEIT-22-2-107 - Leonardo 2026 | I14: Leonardo - Manager Assignment Extention | J14: 9890
F15: Leonardo - Manager Assignment Estensione | G15: Inserita | H15: LUXO-BLUEIT-22-2-109 - Leonardo - Fe Support 2026 | I15: Leonardo - Manager Assignment Extention | J15: 3870
G16: Inserita | I16: Leonardo - Manager Assignment Extention | J16: 4000
M17: 175817 | N17: 1770
M18: 152282.86 | N18: 10373.14 | R18: REYIT26-02346 | S18: 4554126129 | T18: Blue-Ecomm | U18: LUXO-BLUEIT-22-2-90 | V18: 11391
H19: LUXO-BLUEIT-22-2-107 - Leonardo 2026 | I19: Leonardo - Migration to NAM | J19: 2300 | M19: =M18+N18+N17 -> 164426 | R19: REYIT26-02346 | S19: 4554126129 | T19: Blue-Ecomm | U19: LUXO-BLUEIT-22-2-107 | V19: =4519+4000 -> 8519
H20: LUXO-BLUEIT-22-2-107 - Leonardo 2026 | I20: Leonardo - Migration to NAM | J20: 3870 | M20: =M17-M19 -> 11391 | R20: REYIT26-02346 | S20: 4554126129 | T20: Blue-Ecomm | U20: LUXO-BLUEIT-22-2-109 | V20: 6020
H21: LUXO-BLUEIT-22-2-107 - Leonardo 2026 | I21: Leonardo - Migration to NAM | J21: 6730
I22: Leonardo - Migration to NAM | J22: 4000 | R22: REYIT26-02352 | S22: 4554126127 | T22: Blue-Ecomm | U22: LUXO-BLUEIT-22-2-107 | V22: 14110
H23: LUXO-BLUEIT-22-2-107 - Leonardo 2026 | I23: Leonardo - Migration to NAM | J23: 2150 | R23: REYIT26-02352 | S23: 4554126127 | T23: Blue-Ecomm | U23: LUXO-BLUEIT-22-2-109 | V23: 1720
M24: 26369 | N24: 21850 | R24: REYIT26-02352 | S24: 4554126127 | T24: Liquid | U24: LUXO-BLUEIT-22-2-122 | V24: 1500
M25: 54.5 | N25: =(N24/9600)*20 -> 45.520833
M26: =(M24/M25)*20 -> 9676.6972 | R26: REYIT26-02349 | S26: 4554126126 | T26: Blue-Ecomm | U26: LUXO-BLUEIT-25-75-4 | V26: =M7-V30 -> 8265
M27: =M26*20 -> 193533.94 | R27: REYIT26-02349 | S27: 4554126126 | T27: Blue-Ecomm | U27: LUXO-BLUEIT-22-2-109 | V27: 3870
I28: Leonardo - Rating Deprecation | R28: REYIT26-02349 | S28: 4554126126 | T28: Blue-Ecomm | U28: LUXO-BLUEIT-22-2-107 | V28: 5625
I29: Leonardo - Upgrade Coremedia 12 CMS ONE
I30: Leonardo - Program Simplification Backend | R30: REYIT26-02348 | S30: 4554126125 | T30: Blue-Ecomm | U30: LUXO-BLUEIT-25-75-4 | V30: 19050
I31: Leonardo - Deprecation Coins DBA Support
R32: REYIT26-02354 | S32: 4554126128 | T32: Blue-Ecomm | U32: LUXO-BLUEIT-22-2-110 | V32: 7740

Sheet Activities - VIVA
A1: ID | B1: Attività | C1: Data iniziativa | D1: Ref. Luxottica | E1: Codice REY | F1: Ref. Stima | G1: Stato | H1: Importo | I1: Importo scontato | J1: Sconto % | K1: B2B - CTIA | L1: FE | M1: CMS | N1: BFF | O1: B2C | P1: Altri team | Q1: Riferimento stima | R1: Old stima
B2: Recall App 2025
B3: Recall App 2025 - Extra
B4: SAP Integration | D4: Minoia | F4: Losi | G4: 1. Stima inviata | H4: 39130 | K4: =H4-L4 -> 33970 | L4: 5160
B5: PDF in App | D5: Minoia | F5: Losi | G5: 1. Stima inviata | H5: 15050 | K5: =H5-L5 -> 15050 | L5: 0
B6: Model Stock, Completion Report & Small Enhancement | D6: Minoia | F6: Losi | G6: 1. Stima inviata | H6: 25800 | K6: 25800
B7: Backoffice for Power User | D7: Minoia | F7: Losi | G7: 1. Stima inviata | H7: 40850 | K7: 33970 | L7: 6880
B8: Live Report | D8: Minoia | F8: Losi | G8: 1. Stima inviata | H8: 29670 | K8: 29670
B9: AMS VIVA - 2026 | D9: Minoia | F9: Losi | G9: 1. Stima inviata | H9: 141000 | K9: =H9-L9 -> 101000 | L9: 40000
B10: Android version & New MDM Integration | D10: Minoia | F10: Losi | G10: 1. Stima inviata | H10: 32035 | K10: =H10-L10 -> 15265 | L10: =39*430 -> 16770
B11: OSDonation Integration | D11: Minoia | F11: Losi | G11: 1. Stima inviata | H11: 29885 | K11: =H11-L11 -> 22145 | L11: =18*430 -> 7740
B12: Labor Report | D12: Minoia | F12: Losi | G12: 1. Stima inviata | H12: 18705 | K12: 18705

Sheet Budget Lines - VIVA
A1: ID | B1: Nome | C1: Activities | D1: Stato | E1: Commessa | F1: Offers | G1: Importo
C2: Recall App 2025 | D2: Inserita | E2: LUXO-BLUEIT-25-75-3 - Recall App 2025 | G2: 158410
C3: Recall App 2025 | D3: Inserita | E3: LUXO-BLUEIT-25-75-4 - Recall App 2025 | G3: 20500
C4: Recall App 2025 - Extra | D4: Inserita | E4: LUXO-BLUEIT-25-75-4 - Recall App 2025 | G4: 4700
C5: Recall App 2025 - Extra | D5: Inserita | E5: LUXO-BLUEIT-25-75-5 - Recall APP - Formazione 2025 | G5: 10735
B6: Altro - VIVA 2025 | C6: Recall App 2025 | D6: Inserita | E6: LUXO-BLUEIT-25-75-4 - Recall App 2025 | F6: Leonardo - Coins Deprecation | G6: 4000
B7: Altro - VIVA 2025 | C7: Recall App 2025 | D7: Inserita | E7: LUXO-BLUEIT-25-75-4 - Recall App 2025 | F7: Leonardo - Massive_Retraining | G7: 4000
B8: Altro - VIVA 2025 | C8: Recall App 2025 | D8: Inserita | E8: LUXO-BLUEIT-25-75-4 - Recall App 2025 | F8: Leonardo - Manager Assignment Extention | G8: 4000
B9: Altro - VIVA 2025 | C9: Recall App 2025 | D9: Inserita | E9: LUXO-BLUEIT-25-75-4 - Recall App 2025 | F9: Leonardo - Migration to NAM | G9: 4000
B10: Altro - VIVA 2025 | C10: Recall App 2025 | D10: Inserita | E10: LUXO-BLUEIT-25-75-4 - Recall App 2025 | F10: Leonardo - Program Simplification New UI | G10: 7000
B11: Altro - VIVA 2025 | C11: Recall App 2025 | D11: Inserita | E11: LUXO-BLUEIT-25-75-4 - Recall App 2025 | F11: Leonardo - Log Activation W1 | G11: 4315
B12: 01 - SAP Integration | C12: SAP Integration | D12: Inserita | E12: LUXO-BLUEIT-25-75-6 - Recall APP 2026 | F12: VIVA App - SAP Integration [Standard Recall] | G12: 37456
B13: 02 - Active Excess e On Hand Negativo | C13: PDF in App | D13: Inserita | E13: LUXO-BLUEIT-25-75-6 - Recall APP 2026 | F13: VIVA App - PDF in App | G13: 13050 | I13: da correggere nome estensione da active excess in pdf in app
B14: 03 - PDF in app | C14: Model Stock, Completion Report & Small Enhancement | D14: Inserita | E14: LUXO-BLUEIT-25-75-6 - Recall APP 2026 | F14: VIVA App - Model Stock, Completion Report & Small Enhancement | G14: 17090 | I14: da correggere nome estensione da pdf in app a modelstock, completion report
B15: Baseline | C15: Model Stock, Completion Report & Small Enhancement | D15: Inserita | E15: LUXO-BLUEIT-25-75-8 - Recall APP 2026 | F15: VIVA App - Model Stock, Completion Report & Small Enhancement | G15: 5160
B16: 04 - Backoffice for Power User | C16: Backoffice for Power User | D16: Inserita | E16: LUXO-BLUEIT-25-75-6 - Recall APP 2026 | F16: VIVA - Backoffice for Power User | G16: 40850
B17: 05 - Live Report | C17: Live Report | D17: Inserita | E17: LUXO-BLUEIT-25-75-6 - Recall APP 2026 | F17: VIVA - Live Report | G17: 29670
C18: AMS VIVA - 2026 | D18: Inserita | E18: LUXO-BLUEIT-25-75-12 - Recall App - Sessioni 2026 | F18: AMS VIVA App [Mobile] | G18: 25000
C19: AMS VIVA - 2026 | D19: Inserita | E19: LUXO-BLUEIT-25-75-12 - Recall App - Sessioni 2026 | F19: VIVA - CR Pack Q2 | G19: 15000 | K19: =40-22.5 -> 17.5
C20: AMS VIVA - 2026 | D20: Inserita | E20: LUXO-BLUEIT-25-75-10 - Recall App - Sessioni 2026 | F20: AMS VIVA App [Backend] | G20: 25000 | K20: =36-22.5 -> 13.5
C21: AMS VIVA - 2026 | D21: Inserita | E21: LUXO-BLUEIT-25-75-10 - Recall App - Sessioni 2026 | F21: VIVA - CR Pack Q3 | G21: 11000
C22: AMS VIVA - 2026 | D22: Inserita | E22: LUXO-BLUEIT-25-75-6 - Recall APP 2026 | F22: AMS VIVA App [DevOps] | G22: 25000 | K22: =30-22.5 -> 7.5
C23: AMS VIVA - 2026 | D23: Inserita | E23: LUXO-BLUEIT-25-75-6 - Recall APP 2026 | F23: VIVA - CR Pack Q3 | G23: 5000
C24: AMS VIVA - 2026 | D24: Da inserire | E24: LUXO-BLUEIT-25-75-6 - Recall APP 2026 | F24: VIVA - CR Pack Q4 | G24: 21000 | K24: =22.5+22.5+30 -> 75
C25: AMS VIVA - 2026 | D25: Da inserire | E25: LUXO-BLUEIT-25-75-9 - Recall APP - Anticipo 2026 | F25: VIVA - CR Pack Q4 | G25: 9000 | K25: =K24-66 -> 9
C26: AMS VIVA - 2026 | D26: Da inserire | E26: LUXO-BLUEIT-25-75-6 - Recall APP 2026 | F26: VIVA - CR Pack Q2 | G26: 7500
C27: AMS VIVA - 2026 | D27: Da inserire | E27: LUXO-BLUEIT-25-75-6 - Recall APP 2026 | F27: VIVA - CR Pack Q3 | G27: 6500
C28: Android version & New MDM Integration | D28: Da inserire | E28: LUXO-BLUEIT-25-75-6 - Recall APP 2026 | F28: VIVA - Android version & New MDM Integration | G28: 14405
C29: Android version & New MDM Integration | D29: Inserita | E29: LUXO-BLUEIT-25-75-8 - Recall APP 2026 | F29: VIVA - Android version & New MDM Integration | G29: 16770
C30: OSDonation Integration | D30: Da inserire | E30: LUXO-BLUEIT-25-75-6 - Recall APP 2026 | F30: VIVA - OSDonation Integration | G30: 22145
C31: OSDonation Integration | D31: Inserita | E31: LUXO-BLUEIT-25-75-8 - Recall APP 2026 | F31: VIVA - OSDonation Integration | G31: 7740
B32: 06 - Labor Report | C32: Labor Report | D32: Inserita | E32: LUXO-BLUEIT-25-75-6 - Recall APP 2026 | F32: VIVA - Labor Report | G32: 18705
D33: Da inserire | E33: LUXO-BLUEIT-25-75-9 - Recall APP - Anticipo 2026 | F33: VIVA - Upgrade ReactNative & other outdated components | G33: 7994 | H33: a coprire il taglio
D34: Da inserire | E34: LUXO-BLUEIT-25-75-9 - Recall APP - Anticipo 2026 | F34: VIVA - Upgrade ReactNative & other outdated components | G34: 7486 | H34: anticipo per eventuale nuovo taglio
D35: Da inserire | E35: LUXO-BLUEIT-25-75-9 - Recall APP - Anticipo 2026 | F35: VIVA - Extra support x OSDonation Sessions 2026 | G35: 7500
D36: Da inserire | E36: LUXO-BLUEIT-25-75-9 - Recall APP - Anticipo 2026 | F36: VIVA - Extra support x OSDonation Sessions 2026 | G36: 5000

Sheet Activities - Intranet
A1: ID | B1: Attività | C1: Ref. Luxottica | D1: Codice REY | E1: Ref. Stima | F1: Stato | G1: Importo | H1: Importo scontato | I1: Sconto % | J1: B2B - CTIA | K1: FE | L1: CMS | M1: BFF | N1: B2C | O1: Altri team | P1: Riferimento stima | Q1: Old stima
B2: OEL - Welfare Q1 2026 | C2: Carlo Stella | E2: Losi | F2: 4. Offerta Inviata IT | G2: 12900 | J2: 6665 | O2: 6235 | P2: https://reply.sharepoint.com/:x:/r/sites/EL-Intranet-stimeepiani/Shared%20Documents/stime%20e%20piani/2026/INVIATE/OEL_2026_Q1.xlsx?d=wefca6ec0f8d144e8a876138d574bb3eb&csf=1&web=1&e=Uwuwaf
B3: OEL - Release to be quoted | C3: Carlo Stella | E3: Losi | F3: 2. Stima approvata | G3: 5912.5 | J3: 3117.5 | L3: 2365 | P3: https://reply.sharepoint.com/:x:/r/sites/EL-Intranet-stimeepiani/_layouts/15/Doc.aspx?sourcedoc=%7BB37B5954-6F19-4F45-80CD-80A0AB459342%7D&file=OEL%20-%20%20Release%20To%20Be%20Quoted.xlsx&action=default&mobileredirect=true
B4: OEL - Upgrade TT | C4: Carlo Stella | E4: Losi | F4: 2. Stima approvata | G4: =SUM(H4:O4) -> 4300 | O4: 4300

Sheet Budget Lines - Intranet
A1: ID | B1: Nome | C1: Activities | D1: Stato | E1: Commessa | F1: Offers | G1: Importo
B2: Welfare Q1 2026 | C2: OEL - Welfare Q1 2026 | D2: Inserita | E2: LUXO-BLUEIT-22-11-52 - Intranet 2026 | F2: Intranet - Evolutions Q1 | G2: 6665
B3: Welfare Q1 2026 | C3: OEL - Welfare Q1 2026 | D3: Inserita | E3: LUXO-BLUEIT-22-11-61 - TT - Intranet 2026 | F3: Intranet - Evolutions Q1 | G3: 5336
B4: Welfare Q1 2026 | C4: OEL - Welfare Q1 2026 | D4: Da inserire | E4: LUXO-BLUEIT-22-11-61 - TT - Intranet 2026 | F4: Intranet - Evolutions Q1 | G4: 899
B5: Release Q3 | C5: OEL - Release to be quoted | D5: Inserita | E5: LUXO-BLUEIT-22-11-52 - Intranet 2026 | F5: Intranet - Hub Improvements and Video upload for widget | G5: 3117.5
B6: Release Q3 | C6: OEL - Release to be quoted | D6: Inserita | E6: LUXO-BLUEIT-22-11-57 - EL - Intranet CMS - 2026 | F6: Intranet - Hub Improvements and Video upload for widget | G6: 2365
C7: OEL - Upgrade TT | D7: Inserita | E7: LUXO-BLUEIT-22-11-61 - TT - Intranet 2026 | F7: Intranet - Upgrade TT | G7: 3680
C8: OEL - Upgrade TT | D8: Da inserire | E8: LUXO-BLUEIT-22-11-52 - Intranet 2026 | F8: Intranet - Upgrade TT | G8: 620

Sheet Commesse
A1: ID | B1: Anno | C1: Nome | D1: Codice | E1: Nome-Codice | F1: Progetto | G1: BU | H1: Budget | I1: Tipologia | J1: Stato | K1: Colonna2
D2: XXX-XXX-XTECH | E2: =_xlfn.CONCAT(D2," - ",C2) -> XXX-XXX-XTECH - | G2: XTECH | H2: {=SUMPRODUCT(('Budget Lines - Leonardo'!$E$2:$E$1526=Tabella2[[#This Row],[Nome-Codice]])*('Budget Lines - Leonardo'!$G$2:$G$1526))} -> 66550
D3: XXX-XXX-WDWP | E3: =_xlfn.CONCAT(D3," - ",C3) -> XXX-XXX-WDWP - | G3: WDWP | H3: {=SUMPRODUCT(('Budget Lines - Leonardo'!$E$2:$E$1526=Tabella2[[#This Row],[Nome-Codice]])*('Budget Lines - Leonardo'!$G$2:$G$1526))} -> 253550
D4: XXX-XXX-TT | E4: =_xlfn.CONCAT(D4," - ",C4) -> XXX-XXX-TT - | G4: TamTamy | H4: {=SUMPRODUCT(('Budget Lines - Leonardo'!$E$2:$E$1526=Tabella2[[#This Row],[Nome-Codice]])*('Budget Lines - Leonardo'!$G$2:$G$1526))} -> 0
D5: XXX-DPM-ITO | E5: =_xlfn.CONCAT(D5," - ",C5) -> XXX-DPM-ITO - | G5: Liquid_DPM | H5: {=SUMPRODUCT(('Budget Lines - Leonardo'!$E$2:$E$1526=Tabella2[[#This Row],[Nome-Codice]])*('Budget Lines - Leonardo'!$G$2:$G$1526))} -> 5000
D6: XXX-MCI-ITO | E6: =_xlfn.CONCAT(D6," - ",C6) -> XXX-MCI-ITO - | G6: Liquid_MCI | H6: {=SUMPRODUCT(('Budget Lines - Leonardo'!$E$2:$E$1526=Tabella2[[#This Row],[Nome-Codice]])*('Budget Lines - Leonardo'!$G$2:$G$1526))} -> 61245
D7: XXX-DBA | E7: =_xlfn.CONCAT(D7," - ",C7) -> XXX-DBA - | H7: {=SUMPRODUCT(('Budget Lines - Leonardo'!$E$2:$E$1526=Tabella2[[#This Row],[Nome-Codice]])*('Budget Lines - Leonardo'!$G$2:$G$1526))} -> 5000
C8: Leonardo 2024 | D8: LUXO-BLUEIT-22-2-75 | E8: =_xlfn.CONCAT(D8," - ",C8) -> LUXO-BLUEIT-22-2-75 - Leonardo 2024 | F8: Leonardo | G8: CT&IA | H8: {=SUMPRODUCT(('Budget Lines - Leonardo'!$E$2:$E$1526=Tabella2[[#This Row],[Nome-Codice]])*('Budget Lines - Leonardo'!$G$2:$G$1526))} -> 163240
B9: 2025 | C9: Leonardo 2025 | D9: LUXO-BLUEIT-22-2-90 | E9: =_xlfn.CONCAT(D9," - ",C9) -> LUXO-BLUEIT-22-2-90 - Leonardo 2025 | F9: Leonardo | G9: CT&IA | H9: {=SUMPRODUCT(('Budget Lines - Leonardo'!$E$2:$E$1526=Tabella2[[#This Row],[Nome-Codice]])*('Budget Lines - Leonardo'!$G$2:$G$1526))} -> 175817
C10: AM Leonardo 2024 | D10: LUXO-BLUEIT-22-2-78 | E10: =_xlfn.CONCAT(D10," - ",C10) -> LUXO-BLUEIT-22-2-78 - AM Leonardo 2024 | F10: Leonardo | G10: CT&IA | H10: {=SUMPRODUCT(('Budget Lines - Leonardo'!$E$2:$E$1526=Tabella2[[#This Row],[Nome-Codice]])*('Budget Lines - Leonardo'!$G$2:$G$1526))} -> 2000
B11: 2025 | C11: AM Leonardo 2025 | E11: =_xlfn.CONCAT(D11," - ",C11) -> - AM Leonardo 2025 | F11: Leonardo | G11: CT&IA | H11: {=SUMPRODUCT(('Budget Lines - Leonardo'!$E$2:$E$1526=Tabella2[[#This Row],[Nome-Codice]])*('Budget Lines - Leonardo'!$G$2:$G$1526))} -> 0
B12: 2025 | C12: Leonardo 2025 - Formazione | E12: =_xlfn.CONCAT(D12," - ",C12) -> - Leonardo 2025 - Formazione | F12: Leonardo | G12: CT&IA | H12: {=SUMPRODUCT(('Budget Lines - Leonardo'!$E$2:$E$1526=Tabella2[[#This Row],[Nome-Codice]])*('Budget Lines - Leonardo'!$G$2:$G$1526))} -> 0
C13: Leonardo 2024 - Formazione | D13: LUXO-BLUEIT-22-2-81 | E13: =_xlfn.CONCAT(D13," - ",C13) -> LUXO-BLUEIT-22-2-81 - Leonardo 2024 - Formazione | F13: Leonardo | G13: CT&IA | H13: {=SUMPRODUCT(('Budget Lines - Leonardo'!$E$2:$E$1526=Tabella2[[#This Row],[Nome-Codice]])*('Budget Lines - Leonardo'!$G$2:$G$1526))} -> 2200
C14: Leonardo - Fe Support 2025 | D14: LUXO-BLUEIT-22-2-89 | E14: =_xlfn.CONCAT(D14," - ",C14) -> LUXO-BLUEIT-22-2-89 - Leonardo - Fe Support 2025 | F14: Leonardo | G14: XTECH | H14: {=SUMPRODUCT(('Budget Lines - Leonardo'!$E$2:$E$1526=Tabella2[[#This Row],[Nome-Codice]])*('Budget Lines - Leonardo'!$G$2:$G$1526))} -> 113890
B15: 2025 | C15: Leonardo formazione 2025 | D15: LUXO-BLUEIT-22-2-103 | E15: =_xlfn.CONCAT(D15," - ",C15) -> LUXO-BLUEIT-22-2-103 - Leonardo formazione 2025 | F15: Leonardo | G15: CT&IA | H15: {=SUMPRODUCT(('Budget Lines - Leonardo'!$E$2:$E$1526=Tabella2[[#This Row],[Nome-Codice]])*('Budget Lines - Leonardo'!$G$2:$G$1526))} -> 35775
C16: Leonardo - Fe Support 2024 | D16: LUXO-BLUEIT-22-2-69 | E16: =_xlfn.CONCAT(D16," - ",C16) -> LUXO-BLUEIT-22-2-69 - Leonardo - Fe Support 2024 | F16: Leonardo | G16: XTECH | H16: {=SUMPRODUCT(('Budget Lines - Leonardo'!$E$2:$E$1526=Tabella2[[#This Row],[Nome-Codice]])*('Budget Lines - Leonardo'!$G$2:$G$1526))} -> 36627
B17: 2025 | C17: Leonardo formazione 2025 H2 | D17: LUXO-BLUEIT-22-2-106 | E17: =_xlfn.CONCAT(D17," - ",C17) -> LUXO-BLUEIT-22-2-106 - Leonardo formazione 2025 H2 | F17: Leonardo | G17: CT&IA | H17: {=SUMPRODUCT(('Budget Lines - Leonardo'!$E$2:$E$1526=Tabella2[[#This Row],[Nome-Codice]])*('Budget Lines - Leonardo'!$G$2:$G$1526))} -> 29086
B18: 2025 | C18: Leonardo - Quality 2025 | D18: LUXO-BLUEIT-22-2-91 | E18: =_xlfn.CONCAT(D18," - ",C18) -> LUXO-BLUEIT-22-2-91 - Leonardo - Quality 2025 | F18: Leonardo | G18: XTECH | H18: {=SUMPRODUCT(('Budget Lines - Leonardo'!$E$2:$E$1526=Tabella2[[#This Row],[Nome-Codice]])*('Budget Lines - Leonardo'!$G$2:$G$1526))} -> 123195
B19: 2025 | C19: Leonardo Quality 2025 | D19: LUXO-BLUEIT-22-2-94 | E19: =_xlfn.CONCAT(D19," - ",C19) -> LUXO-BLUEIT-22-2-94 - Leonardo Quality 2025 | F19: Leonardo | G19: CT&IA | H19: {=SUMPRODUCT(('Budget Lines - Leonardo'!$E$2:$E$1526=Tabella2[[#This Row],[Nome-Codice]])*('Budget Lines - Leonardo'!$G$2:$G$1526))} -> 274340
B20: 2025 | C20: Leonardo Quality 2025 - Residuo | D20: LUXO-BLUEIT-22-2-100 | E20: =_xlfn.CONCAT(D20," - ",C20) -> LUXO-BLUEIT-22-2-100 - Leonardo Quality 2025 - Residuo | F20: Leonardo | G20: CT&IA | H20: {=SUMPRODUCT(('Budget Lines - Leonardo'!$E$2:$E$1526=Tabella2[[#This Row],[Nome-Codice]])*('Budget Lines - Leonardo'!$G$2:$G$1526))} -> 19780
B21: 2026 | C21: Leonardo 2026 | D21: LUXO-BLUEIT-22-2-107 | E21: =_xlfn.CONCAT(D21," - ",C21) -> LUXO-BLUEIT-22-2-107 - Leonardo 2026 | F21: Leonardo | G21: CT&IA | H21: {=SUMPRODUCT(('Budget Lines - Leonardo'!$E$2:$E$1526=Tabella2[[#This Row],[Nome-Codice]])*('Budget Lines - Leonardo'!$G$2:$G$1526))} -> 406949
B22: 2025 | C22: Recall APP 2025 | D22: LUXO-BLUEIT-25-75-3 | E22: =_xlfn.CONCAT(D22," - ",C22) -> LUXO-BLUEIT-25-75-3 - Recall APP 2025 | F22: VIVA | G22: CT&IA | H22: {=SUMPRODUCT(('Budget Lines - Leonardo'!$E$2:$E$1526=Tabella2[[#This Row],[Nome-Codice]])*('Budget Lines - Leonardo'!$G$2:$G$1526))} -> 0
B23: 2025 | C23: Recall APP 2025 | D23: LUXO-BLUEIT-25-75-4 | E23: =_xlfn.CONCAT(D23," - ",C23) -> LUXO-BLUEIT-25-75-4 - Recall APP 2025 | F23: VIVA | G23: XTECH | H23: {=SUMPRODUCT(('Budget Lines - Leonardo'!$E$2:$E$1526=Tabella2[[#This Row],[Nome-Codice]])*('Budget Lines - Leonardo'!$G$2:$G$1526))} -> 0
B24: 2025 | C24: Recall APP - Formazione 2025 | D24: LUXO-BLUEIT-25-75-5 | E24: =_xlfn.CONCAT(D24," - ",C24) -> LUXO-BLUEIT-25-75-5 - Recall APP - Formazione 2025 | F24: VIVA | G24: CT&IA | H24: {=SUMPRODUCT(('Budget Lines - Leonardo'!$E$2:$E$1526=Tabella2[[#This Row],[Nome-Codice]])*('Budget Lines - Leonardo'!$G$2:$G$1526))} -> 0
B25: 2026 | C25: Intranet 2026 | D25: LUXO-BLUEIT-22-11-52 | E25: =_xlfn.CONCAT(D25," - ",C25) -> LUXO-BLUEIT-22-11-52 - Intranet 2026 | F25: Intranet | H25: {=SUMPRODUCT(('Budget Lines - Leonardo'!$E$2:$E$1526=Tabella2[[#This Row],[Nome-Codice]])*('Budget Lines - Leonardo'!$G$2:$G$1526))} -> 0
B26: 2026 | C26: TT - Intranet 2026 | D26: LUXO-BLUEIT-22-11-61 | E26: =_xlfn.CONCAT(D26," - ",C26) -> LUXO-BLUEIT-22-11-61 - TT - Intranet 2026 | F26: Intranet | H26: {=SUMPRODUCT(('Budget Lines - Leonardo'!$E$2:$E$1526=Tabella2[[#This Row],[Nome-Codice]])*('Budget Lines - Leonardo'!$G$2:$G$1526))} -> 0
B27: 2026 | C27: Leonardo - Fe Support 2026 | D27: LUXO-BLUEIT-22-2-109 | E27: =_xlfn.CONCAT(D27," - ",C27) -> LUXO-BLUEIT-22-2-109 - Leonardo - Fe Support 2026 | F27: Leonardo | G27: XTECH | H27: {=SUMPRODUCT(('Budget Lines - Leonardo'!$E$2:$E$1526=Tabella2[[#This Row],[Nome-Codice]])*('Budget Lines - Leonardo'!$G$2:$G$1526))} -> 127065
B28: 2026 | C28: Recall APP 2026 | D28: LUXO-BLUEIT-25-75-6 | E28: =_xlfn.CONCAT(D28," - ",C28) -> LUXO-BLUEIT-25-75-6 - Recall APP 2026 | F28: VIVA | G28: CT&IA | H28: {=SUMPRODUCT(('Budget Lines - Leonardo'!$E$2:$E$1526=Tabella2[[#This Row],[Nome-Codice]])*('Budget Lines - Leonardo'!$G$2:$G$1526))} -> 0
B29: 2026 | C29: Recall APP 2026 | D29: LUXO-BLUEIT-25-75-8 | E29: =_xlfn.CONCAT(D29," - ",C29) -> LUXO-BLUEIT-25-75-8 - Recall APP 2026 | F29: VIVA | G29: XTECH | H29: {=SUMPRODUCT(('Budget Lines - Leonardo'!$E$2:$E$1526=Tabella2[[#This Row],[Nome-Codice]])*('Budget Lines - Leonardo'!$G$2:$G$1526))} -> 0
B30: 2026 | C30: Recall App - Sessioni 2026 | D30: LUXO-BLUEIT-25-75-12 | E30: =_xlfn.CONCAT(D30," - ",C30) -> LUXO-BLUEIT-25-75-12 - Recall App - Sessioni 2026 | F30: VIVA | G30: XTECH | H30: {=SUMPRODUCT(('Budget Lines - Leonardo'!$E$2:$E$1526=Tabella2[[#This Row],[Nome-Codice]])*('Budget Lines - Leonardo'!$G$2:$G$1526))} -> 0
B31: 2026 | C31: Recall App - Sessioni 2026 | D31: LUXO-BLUEIT-25-75-10 | E31: =_xlfn.CONCAT(D31," - ",C31) -> LUXO-BLUEIT-25-75-10 - Recall App - Sessioni 2026 | F31: VIVA | G31: CT&IA | H31: {=SUMPRODUCT(('Budget Lines - Leonardo'!$E$2:$E$1526=Tabella2[[#This Row],[Nome-Codice]])*('Budget Lines - Leonardo'!$G$2:$G$1526))} -> 0
B32: 2026 | C32: Leonardo DevOps 2026 | D32: LUXO-BLUEIT-22-2-116 | E32: =_xlfn.CONCAT(D32," - ",C32) -> LUXO-BLUEIT-22-2-116 - Leonardo DevOps 2026 | F32: DevOps | G32: CT&IA | H32: {=SUMPRODUCT(('Budget Lines - Leonardo'!$E$2:$E$1526=Tabella2[[#This Row],[Nome-Codice]])*('Budget Lines - Leonardo'!$G$2:$G$1526))} -> 34615
B33: 2026 | C33: Leonardo DevOps AM 2026 | D33: LUXO-BLUEIT-22-2-118 | E33: =_xlfn.CONCAT(D33," - ",C33) -> LUXO-BLUEIT-22-2-118 - Leonardo DevOps AM 2026 | F33: DevOps | G33: CT&IA | H33: {=SUMPRODUCT(('Budget Lines - Leonardo'!$E$2:$E$1526=Tabella2[[#This Row],[Nome-Codice]])*('Budget Lines - Leonardo'!$G$2:$G$1526))} -> 0
B34: 2026 | C34: EL - Intranet CMS - 2026 | D34: LUXO-BLUEIT-22-11-57 | E34: =_xlfn.CONCAT(D34," - ",C34) -> LUXO-BLUEIT-22-11-57 - EL - Intranet CMS - 2026 | F34: Intranet | G34: DXP | H34: {=SUMPRODUCT(('Budget Lines - Leonardo'!$E$2:$E$1526=Tabella2[[#This Row],[Nome-Codice]])*('Budget Lines - Leonardo'!$G$2:$G$1526))} -> 0
B35: 2026 | C35: Recall APP - Anticipo 2026 | D35: LUXO-BLUEIT-25-75-9 | E35: =_xlfn.CONCAT(D35," - ",C35) -> LUXO-BLUEIT-25-75-9 - Recall APP - Anticipo 2026 | F35: VIVA | G35: CT&IA | H35: {=SUMPRODUCT(('Budget Lines - Leonardo'!$E$2:$E$1526=Tabella2[[#This Row],[Nome-Codice]])*('Budget Lines - Leonardo'!$G$2:$G$1526))} -> 0

Sheet Dati
A1: Stato BL | B1: Stato Offerta | C1: Tipologia Commessa | D1: Stato Commessa
A2: Da inserire | B2: Da fare | C2: RISERVA | D2: Aperta
A3: Inserita | B3: Da Inviare | C3: ANTICIPO | D3: Da aprire
B4: Inviata | C4: SERVIZIO | D4: Chiusa
B5: In attesa ordine | C5: PROGETTO
B6: Fatturata

Sheet Mail
A1: id Conversation | B1: Id Mail | C1: CC Mail | D1: Id Activities | E1: Id Reply | F1: CC Reply
A2: AAQkADIxZjNmYWE2LWYyMWYtNDk2Mi05ZDUzLWI5NjkyOGRhYjc0NQAQAIXp9lkJZkzqkifG9mnSKUU= | B2: AAMkADIxZjNmYWE2LWYyMWYtNDk2Mi05ZDUzLWI5NjkyOGRhYjc0NQBGAAAAAABtXxU4yslUQKe1TjvSuL1eBwD0jDUQAKjpQ4hllEs7xQF9AAAAFWaTAADZpw6ZQmTUTZI4GeGUW_WuAAg735cOAAA=
A3: AAQkADIxZjNmYWE2LWYyMWYtNDk2Mi05ZDUzLWI5NjkyOGRhYjc0NQAQAOyXLtE-EkOMhpnyVUR3hA8= | B3: AAMkADIxZjNmYWE2LWYyMWYtNDk2Mi05ZDUzLWI5NjkyOGRhYjc0NQBGAAAAAABtXxU4yslUQKe1TjvSuL1eBwD0jDUQAKjpQ4hllEs7xQF9AAAAFWaTAADZpw6ZQmTUTZI4GeGUW_WuAAg735cRAAA=
A4: AAQkADIxZjNmYWE2LWYyMWYtNDk2Mi05ZDUzLWI5NjkyOGRhYjc0NQAQAKCR5gp0t0c9tJ0SMGd_Uo4= | B4: AAMkADIxZjNmYWE2LWYyMWYtNDk2Mi05ZDUzLWI5NjkyOGRhYjc0NQBGAAAAAABtXxU4yslUQKe1TjvSuL1eBwD0jDUQAKjpQ4hllEs7xQF9AAAAFWaTAADZpw6ZQmTUTZI4GeGUW_WuAAg735c0AAA=
